Workbook

Sheet Export Summary
B3: This document was exported from Numbers. Each table was converted to an Excel worksheet. All other objects on each Numbers sheet were placed on separate worksheets. Please be aware that formula calculations may differ in Excel.
B7: Numbers Sheet Name | C7: Numbers Table Name | D7: Excel Worksheet Name
B9: Summary
C10: Table 1 | D10: Summary
B11: Housing Data
C12: Table 1 | D12: Housing Data

Sheet Summary
A2: Sydney Housing Sold-Property Dataset
A5: Dataset measure | B5: Value | D5: Suburb | E5: Records | F5: Average sale price | G5: Minimum | H5: Maximum
A6: Verified properties | B6: =COUNTA('Housing Data'!A2:A106) -> 105 | D6: Blacktown | E6: =_xlfn.COUNTIFS('Housing Data'!C$2:C$106,D6) -> 35 | F6: =_xlfn.AVERAGEIFS('Housing Data'!F$2:F$106,'Housing Data'!C$2:C$106,D6) -> 1160371.4 | G6: =_xlfn.MINIFS('Housing Data'!F$2:F$106,'Housing Data'!C$2:C$106,D6) -> 820000 | H6: =_xlfn.MAXIFS('Housing Data'!F$2:F$106,'Housing Data'!C$2:C$106,D6) -> 1900000
A7: Suburbs | B7: 3 | D7: Liverpool | E7: =_xlfn.COUNTIFS('Housing Data'!C$2:C$106,D7) -> 35 | F7: =_xlfn.AVERAGEIFS('Housing Data'!F$2:F$106,'Housing Data'!C$2:C$106,D7) -> 1225885.7 | G7: =_xlfn.MINIFS('Housing Data'!F$2:F$106,'Housing Data'!C$2:C$106,D7) -> 390000 | H7: =_xlfn.MAXIFS('Housing Data'!F$2:F$106,'Housing Data'!C$2:C$106,D7) -> 3100000
A8: Properties within $800k–$1.2m | B8: =_xlfn.COUNTIFS('Housing Data'!M2:M106,"Yes") -> 66 | D8: Campbelltown | E8: =_xlfn.COUNTIFS('Housing Data'!C$2:C$106,D8) -> 35 | F8: =_xlfn.AVERAGEIFS('Housing Data'!F$2:F$106,'Housing Data'!C$2:C$106,D8) -> 1005387.3 | G8: =_xlfn.MINIFS('Housing Data'!F$2:F$106,'Housing Data'!C$2:C$106,D8) -> 510000 | H8: =_xlfn.MAXIFS('Housing Data'!F$2:F$106,'Housing Data'!C$2:C$106,D8) -> 1750000
A9: Missing land size | B9: =COUNTBLANK('Housing Data'!K2:K106) -> 29 | D9: Total | E9: =SUM(E6:E8) -> 105 | F9: =AVERAGE('Housing Data'!F2:F106) -> 1130548.1 | G9: =MIN('Housing Data'!F2:F106) -> 390000 | H9: =MAX('Housing Data'!F2:F106) -> 3100000
A10: Collection date | B10: 46282
A12: Dataset notes
A13: Scope | B13: Recent publicly displayed sold-house listings for Blacktown, Liverpool and Campbelltown. Each row retains its direct listing and source-page URL.
A14: Missing values | B14: Blank cells mean the source listing did not publicly display that feature. Missing land size was not estimated.
A15: Use | B15: Suitable as a starting dataset for coursework exploration and model development. Recheck source pages before final submission because public listings may change.
A16: Primary source | B16: realestate.com.au sold-property pages.
A17: Secondary reference | B17: domain.com.au was supplied as an alternative property-data website; no Domain values were merged to avoid duplicate or conflicting records.

Sheet Housing Data
A1: Property_ID | B1: Address | C1: Suburb | D1: State | E1: Postcode | F1: Sale_Price_AUD | G1: Sale_Date | H1: Bedrooms | I1: Bathrooms | J1: Parking_Spaces | K1: Land_Size_m2 | L1: Property_Type | M1: Within_Budget_800k_1.2m | N1: Listing_URL | O1: Source_Page | P1: Source_Website | Q1: Collected_On
A2: SYD-001 | B2: 40 Stephen Street, Blacktown | C2: Blacktown | D2: NSW | E2: 2148 | F2: 1350000 | G2: 46282 | H2: 5 | I2: 3 | J2: 3 | K2: 338 | L2: House | M2: =IF(AND(F2>=800000,F2<=1200000),"Yes","No") -> No | N2: https://www.realestate.com.au/sold/property-house-nsw-blacktown-151437264 | O2: https://www.realestate.com.au/sold/property-house-in-blacktown%2C%2Bnsw%2B2148/list-1 | P2: realestate.com.au | Q2: 46282
A3: SYD-002 | B3: 7 Highlands Crescent, Blacktown | C3: Blacktown | D3: NSW | E3: 2148 | F3: 1135000 | G3: 46280 | H3: 3 | I3: 2 | J3: 4 | K3: 765 | L3: House | M3: =IF(AND(F3>=800000,F3<=1200000),"Yes","No") -> Yes | N3: https://www.realestate.com.au/sold/property-house-nsw-blacktown-152114604 | O3: https://www.realestate.com.au/sold/property-house-in-blacktown%2C%2Bnsw%2B2148/list-1 | P3: realestate.com.au | Q3: 46282
A4: SYD-003 | B4: 81 Reservoir Road, Blacktown | C4: Blacktown | D4: NSW | E4: 2148 | F4: 1105000 | G4: 46280 | H4: 4 | I4: 2 | J4: 2 | L4: House | M4: =IF(AND(F4>=800000,F4<=1200000),"Yes","No") -> Yes | N4: https://www.realestate.com.au/sold/property-house-nsw-blacktown-150847848 | O4: https://www.realestate.com.au/sold/property-house-in-blacktown%2C%2Bnsw%2B2148/list-1 | P4: realestate.com.au | Q4: 46282
A5: SYD-004 | B5: 4 & 4A Joseph Street, Blacktown | C5: Blacktown | D5: NSW | E5: 2148 | F5: 1340000 | G5: 46279 | H5: 5 | I5: 2 | J5: 1 | K5: 713 | L5: House | M5: =IF(AND(F5>=800000,F5<=1200000),"Yes","No") -> No | N5: https://www.realestate.com.au/sold/property-house-nsw-blacktown-151882968 | O5: https://www.realestate.com.au/sold/property-house-in-blacktown%2C%2Bnsw%2B2148/list-1 | P5: realestate.com.au | Q5: 46282
A6: SYD-005 | B6: 42 Burke Street, Blacktown | C6: Blacktown | D6: NSW | E6: 2148 | F6: 1260000 | G6: 46276 | H6: 5 | I6: 3 | J6: 6 | L6: House | M6: =IF(AND(F6>=800000,F6<=1200000),"Yes","No") -> No | N6: https://www.realestate.com.au/sold/property-house-nsw-blacktown-151994180 | O6: https://www.realestate.com.au/sold/property-house-in-blacktown%2C%2Bnsw%2B2148/list-1 | P6: realestate.com.au | Q6: 46282
A7: SYD-006 | B7: 52 Balmoral Street, Blacktown | C7: Blacktown | D7: NSW | E7: 2148 | F7: 1300000 | G7: 46273 | H7: 4 | I7: 1 | J7: 1 | K7: 696.77 | L7: House | M7: =IF(AND(F7>=800000,F7<=1200000),"Yes","No") -> No | N7: https://www.realestate.com.au/sold/property-house-nsw-blacktown-149983288 | O7: https://www.realestate.com.au/sold/property-house-in-blacktown%2C%2Bnsw%2B2148/list-1 | P7: realestate.com.au | Q7: 46282
A8: SYD-007 | B8: 9 Kirkman Road, Blacktown | C8: Blacktown | D8: NSW | E8: 2148 | F8: 1070000 | G8: 46268 | H8: 4 | I8: 1 | J8: 2 | K8: 638 | L8: House | M8: =IF(AND(F8>=800000,F8<=1200000),"Yes","No") -> Yes | N8: https://www.realestate.com.au/sold/property-house-nsw-blacktown-152024064 | O8: https://www.realestate.com.au/sold/property-house-in-blacktown%2C%2Bnsw%2B2148/list-1 | P8: realestate.com.au | Q8: 46282
A9: SYD-008 | B9: 17 Carinya Street, Blacktown | C9: Blacktown | D9: NSW | E9: 2148 | F9: 1600000 | G9: 46266 | H9: 3 | I9: 1 | J9: 1 | K9: 1182.4 | L9: House | M9: =IF(AND(F9>=800000,F9<=1200000),"Yes","No") -> No | N9: https://www.realestate.com.au/sold/property-house-nsw-blacktown-151555988 | O9: https://www.realestate.com.au/sold/property-house-in-blacktown%2C%2Bnsw%2B2148/list-1 | P9: realestate.com.au | Q9: 46282
A10: SYD-009 | B10: 38-38A Burrell Parade, Blacktown | C10: Blacktown | D10: NSW | E10: 2148 | F10: 1480000 | G10: 46262 | H10: 5 | I10: 3 | J10: 4 | K10: 563 | L10: House | M10: =IF(AND(F10>=800000,F10<=1200000),"Yes","No") -> No | N10: https://www.realestate.com.au/sold/property-house-nsw-blacktown-151694540 | O10: https://www.realestate.com.au/sold/property-house-in-blacktown%2C%2Bnsw%2B2148/list-1 | P10: realestate.com.au | Q10: 46282
A11: SYD-010 | B11: 39 Burke Street, Blacktown | C11: Blacktown | D11: NSW | E11: 2148 | F11: 1500000 | G11: 46260 | H11: 5 | I11: 3 | J11: 2 | L11: House | M11: =IF(AND(F11>=800000,F11<=1200000),"Yes","No") -> No | N11: https://www.realestate.com.au/sold/property-house-nsw-blacktown-151775940 | O11: https://www.realestate.com.au/sold/property-house-in-blacktown%2C%2Bnsw%2B2148/list-1 | P11: realestate.com.au | Q11: 46282
A12: SYD-011 | B12: 19 Stephen Street, Blacktown | C12: Blacktown | D12: NSW | E12: 2148 | F12: 1062500 | G12: 46260 | H12: 3 | I12: 1 | J12: 1 | K12: 575.4 | L12: House | M12: =IF(AND(F12>=800000,F12<=1200000),"Yes","No") -> Yes | N12: https://www.realestate.com.au/sold/property-house-nsw-blacktown-152017640 | O12: https://www.realestate.com.au/sold/property-house-in-blacktown%2C%2Bnsw%2B2148/list-1 | P12: realestate.com.au | Q12: 46282
A13: SYD-012 | B13: 130 Bungarribee Road, Blacktown | C13: Blacktown | D13: NSW | E13: 2148 | F13: 1150000 | G13: 46258 | H13: 3 | I13: 1 | J13: 1 | K13: 670 | L13: House | M13: =IF(AND(F13>=800000,F13<=1200000),"Yes","No") -> Yes | N13: https://www.realestate.com.au/sold/property-house-nsw-blacktown-151535008 | O13: https://www.realestate.com.au/sold/property-house-in-blacktown%2C%2Bnsw%2B2148/list-1 | P13: realestate.com.au | Q13: 46282
A14: SYD-013 | B14: 36 Bedford Road, Blacktown | C14: Blacktown | D14: NSW | E14: 2148 | F14: 1007500 | G14: 46258 | H14: 3 | I14: 2 | J14: 4 | K14: 651 | L14: House | M14: =IF(AND(F14>=800000,F14<=1200000),"Yes","No") -> Yes | N14: https://www.realestate.com.au/sold/property-house-nsw-blacktown-151912132 | O14: https://www.realestate.com.au/sold/property-house-in-blacktown%2C%2Bnsw%2B2148/list-1 | P14: realestate.com.au | Q14: 46282
A15: SYD-014 | B15: 13 Lancaster Street, Blacktown | C15: Blacktown | D15: NSW | E15: 2148 | F15: 1900000 | G15: 46256 | H15: 7 | I15: 4 | J15: 6 | K15: 739.8 | L15: House | M15: =IF(AND(F15>=800000,F15<=1200000),"Yes","No") -> No | N15: https://www.realestate.com.au/sold/property-house-nsw-blacktown-151888376 | O15: https://www.realestate.com.au/sold/property-house-in-blacktown%2C%2Bnsw%2B2148/list-1 | P15: realestate.com.au | Q15: 46282
A16: SYD-015 | B16: 6 Garden Street, Blacktown | C16: Blacktown | D16: NSW | E16: 2148 | F16: 1235000 | G16: 46254 | H16: 4 | I16: 2 | J16: 6 | K16: 556 | L16: House | M16: =IF(AND(F16>=800000,F16<=1200000),"Yes","No") -> No | N16: https://www.realestate.com.au/sold/property-house-nsw-blacktown-151824544 | O16: https://www.realestate.com.au/sold/property-house-in-blacktown%2C%2Bnsw%2B2148/list-1 | P16: realestate.com.au | Q16: 46282
A17: SYD-016 | B17: 94 Lancelot Street, Blacktown | C17: Blacktown | D17: NSW | E17: 2148 | F17: 950000 | G17: 46252 | H17: 3 | I17: 1 | J17: 1 | K17: 562.7 | L17: House | M17: =IF(AND(F17>=800000,F17<=1200000),"Yes","No") -> Yes | N17: https://www.realestate.com.au/sold/property-house-nsw-blacktown-151814988 | O17: https://www.realestate.com.au/sold/property-house-in-blacktown%2C%2Bnsw%2B2148/list-1 | P17: realestate.com.au | Q17: 46282
A18: SYD-017 | B18: 41 Dagmar Crescent, Blacktown | C18: Blacktown | D18: NSW | E18: 2148 | F18: 880000 | G18: 46252 | H18: 3 | I18: 1 | J18: 2 | K18: 569.1 | L18: House | M18: =IF(AND(F18>=800000,F18<=1200000),"Yes","No") -> Yes | N18: https://www.realestate.com.au/sold/property-house-nsw-blacktown-151539124 | O18: https://www.realestate.com.au/sold/property-house-in-blacktown%2C%2Bnsw%2B2148/list-1 | P18: realestate.com.au | Q18: 46282
A19: SYD-018 | B19: 5 Ajax Place, Blacktown | C19: Blacktown | D19: NSW | E19: 2148 | F19: 1000000 | G19: 46251 | H19: 3 | I19: 2 | J19: 2 | L19: House | M19: =IF(AND(F19>=800000,F19<=1200000),"Yes","No") -> Yes | N19: https://www.realestate.com.au/sold/property-house-nsw-blacktown-151708676 | O19: https://www.realestate.com.au/sold/property-house-in-blacktown%2C%2Bnsw%2B2148/list-1 | P19: realestate.com.au | Q19: 46282
A20: SYD-019 | B20: 41 Anthony Street, Blacktown | C20: Blacktown | D20: NSW | E20: 2148 | F20: 910000 | G20: 46251 | H20: 3 | I20: 1 | J20: 1 | L20: House | M20: =IF(AND(F20>=800000,F20<=1200000),"Yes","No") -> Yes | N20: https://www.realestate.com.au/sold/property-house-nsw-blacktown-151862164 | O20: https://www.realestate.com.au/sold/property-house-in-blacktown%2C%2Bnsw%2B2148/list-1 | P20: realestate.com.au | Q20: 46282
A21: SYD-020 | B21: 45 & 45a Dina Beth Avenue, Blacktown | C21: Blacktown | D21: NSW | E21: 2148 | F21: 1250000 | G21: 46248 | H21: 5 | I21: 2 | J21: 4 | L21: House | M21: =IF(AND(F21>=800000,F21<=1200000),"Yes","No") -> No | N21: https://www.realestate.com.au/sold/property-house-nsw-blacktown-151561636 | O21: https://www.realestate.com.au/sold/property-house-in-blacktown%2C%2Bnsw%2B2148/list-1 | P21: realestate.com.au | Q21: 46282
A22: SYD-021 | B22: 28 Eggleton Street, Blacktown | C22: Blacktown | D22: NSW | E22: 2148 | F22: 1263000 | G22: 46247 | H22: 3 | I22: 1 | J22: 2 | L22: House | M22: =IF(AND(F22>=800000,F22<=1200000),"Yes","No") -> No | N22: https://www.realestate.com.au/sold/property-house-nsw-blacktown-151248672 | O22: https://www.realestate.com.au/sold/property-house-in-blacktown%2C%2Bnsw%2B2148/list-1 | P22: realestate.com.au | Q22: 46282
A23: SYD-022 | B23: 12 Glamorgan Street, Blacktown | C23: Blacktown | D23: NSW | E23: 2148 | F23: 1030000 | G23: 46245 | H23: 3 | I23: 1 | J23: 1 | K23: 556 | L23: House | M23: =IF(AND(F23>=800000,F23<=1200000),"Yes","No") -> Yes | N23: https://www.realestate.com.au/sold/property-house-nsw-blacktown-151691880 | O23: https://www.realestate.com.au/sold/property-house-in-blacktown%2C%2Bnsw%2B2148/list-1 | P23: realestate.com.au | Q23: 46282
A24: SYD-023 | B24: 41 Burrell Parade, Blacktown | C24: Blacktown | D24: NSW | E24: 2148 | F24: 960000 | G24: 46245 | H24: 3 | I24: 1 | J24: 2 | K24: 556 | L24: House | M24: =IF(AND(F24>=800000,F24<=1200000),"Yes","No") -> Yes | N24: https://www.realestate.com.au/sold/property-house-nsw-blacktown-151589056 | O24: https://www.realestate.com.au/sold/property-house-in-blacktown%2C%2Bnsw%2B2148/list-1 | P24: realestate.com.au | Q24: 46282
A25: SYD-024 | B25: 24 Twilight Crescent, Blacktown | C25: Blacktown | D25: NSW | E25: 2148 | F25: 1024000 | G25: 46244 | H25: 3 | I25: 2 | J25: 2 | L25: House | M25: =IF(AND(F25>=800000,F25<=1200000),"Yes","No") -> Yes | N25: https://www.realestate.com.au/sold/property-house-nsw-blacktown-151497684 | O25: https://www.realestate.com.au/sold/property-house-in-blacktown%2C%2Bnsw%2B2148/list-1 | P25: realestate.com.au | Q25: 46282
A26: SYD-025 | B26: 57 Walters Road, Blacktown | C26: Blacktown | D26: NSW | E26: 2148 | F26: 1221000 | G26: 46242 | H26: 3 | I26: 1 | J26: 1 | K26: 835 | L26: House | M26: =IF(AND(F26>=800000,F26<=1200000),"Yes","No") -> No | N26: https://www.realestate.com.au/sold/property-house-nsw-blacktown-151780948 | O26: https://www.realestate.com.au/sold/property-house-in-blacktown%2C%2Bnsw%2B2148/list-1 | P26: realestate.com.au | Q26: 46282
A27: SYD-026 | B27: 59 Walters Road, Blacktown | C27: Blacktown | D27: NSW | E27: 2148 | F27: 900000 | G27: 46242 | H27: 3 | I27: 1 | J27: 1 | K27: 562 | L27: House | M27: =IF(AND(F27>=800000,F27<=1200000),"Yes","No") -> Yes | N27: https://www.realestate.com.au/sold/property-house-nsw-blacktown-151632936 | O27: https://www.realestate.com.au/sold/property-house-in-blacktown%2C%2Bnsw%2B2148/list-2 | P27: realestate.com.au | Q27: 46282
A28: SYD-027 | B28: 12 Siebel Street, Blacktown | C28: Blacktown | D28: NSW | E28: 2148 | F28: 1080000 | G28: 46239 | H28: 5 | I28: 2 | J28: 1 | K28: 560 | L28: House | M28: =IF(AND(F28>=800000,F28<=1200000),"Yes","No") -> Yes | N28: https://www.realestate.com.au/sold/property-house-nsw-blacktown-150980712 | O28: https://www.realestate.com.au/sold/property-house-in-blacktown%2C%2Bnsw%2B2148/list-2 | P28: realestate.com.au | Q28: 46282
A29: SYD-028 | B29: 5 Aliberti Drive, Blacktown | C29: Blacktown | D29: NSW | E29: 2148 | F29: 1060000 | G29: 46237 | H29: 3 | I29: 2 | J29: 1 | K29: 441.5 | L29: House | M29: =IF(AND(F29>=800000,F29<=1200000),"Yes","No") -> Yes | N29: https://www.realestate.com.au/sold/property-house-nsw-blacktown-151115652 | O29: https://www.realestate.com.au/sold/property-house-in-blacktown%2C%2Bnsw%2B2148/list-2 | P29: realestate.com.au | Q29: 46282
A30: SYD-029 | B30: 59 Lancaster Street, Blacktown | C30: Blacktown | D30: NSW | E30: 2148 | F30: 900000 | G30: 46234 | H30: 3 | I30: 2 | J30: 3 | K30: 600.7 | L30: House | M30: =IF(AND(F30>=800000,F30<=1200000),"Yes","No") -> Yes | N30: https://www.realestate.com.au/sold/property-house-nsw-blacktown-151619392 | O30: https://www.realestate.com.au/sold/property-house-in-blacktown%2C%2Bnsw%2B2148/list-2 | P30: realestate.com.au | Q30: 46282
A31: SYD-030 | B31: 68 Eggleton Street, Blacktown | C31: Blacktown | D31: NSW | E31: 2148 | F31: 900000 | G31: 46233 | H31: 3 | I31: 1 | J31: 2 | K31: 600 | L31: House | M31: =IF(AND(F31>=800000,F31<=1200000),"Yes","No") -> Yes | N31: https://www.realestate.com.au/sold/property-house-nsw-blacktown-151309196 | O31: https://www.realestate.com.au/sold/property-house-in-blacktown%2C%2Bnsw%2B2148/list-2 | P31: realestate.com.au | Q31: 46282
A32: SYD-031 | B32: 53 Pelleas Street, Blacktown | C32: Blacktown | D32: NSW | E32: 2148 | F32: 1700000 | G32: 46232 | H32: 7 | I32: 4 | J32: 2 | K32: 584 | L32: House | M32: =IF(AND(F32>=800000,F32<=1200000),"Yes","No") -> No | N32: https://www.realestate.com.au/sold/property-house-nsw-blacktown-151489892 | O32: https://www.realestate.com.au/sold/property-house-in-blacktown%2C%2Bnsw%2B2148/list-2 | P32: realestate.com.au | Q32: 46282
A33: SYD-032 | B33: 28 Flyer Glade, Blacktown | C33: Blacktown | D33: NSW | E33: 2148 | F33: 870000 | G33: 46232 | H33: 2 | I33: 2 | J33: 1 | L33: House | M33: =IF(AND(F33>=800000,F33<=1200000),"Yes","No") -> Yes | N33: https://www.realestate.com.au/sold/property-house-nsw-blacktown-150103248 | O33: https://www.realestate.com.au/sold/property-house-in-blacktown%2C%2Bnsw%2B2148/list-2 | P33: realestate.com.au | Q33: 46282
A34: SYD-033 | B34: 1 Tara Road, Blacktown | C34: Blacktown | D34: NSW | E34: 2148 | F34: 820000 | G34: 46232 | H34: 2 | I34: 1 | J34: 2 | K34: 308 | L34: House | M34: =IF(AND(F34>=800000,F34<=1200000),"Yes","No") -> Yes | N34: https://www.realestate.com.au/sold/property-house-nsw-blacktown-151256088 | O34: https://www.realestate.com.au/sold/property-house-in-blacktown%2C%2Bnsw%2B2148/list-2 | P34: realestate.com.au | Q34: 46282
A35: SYD-034 | B35: 9 Nicholas Street, Blacktown | C35: Blacktown | D35: NSW | E35: 2148 | F35: 1200000 | G35: 46231 | H35: 5 | I35: 2 | J35: 1 | K35: 550 | L35: House | M35: =IF(AND(F35>=800000,F35<=1200000),"Yes","No") -> Yes | N35: https://www.realestate.com.au/sold/property-house-nsw-blacktown-151025772 | O35: https://www.realestate.com.au/sold/property-house-in-blacktown%2C%2Bnsw%2B2148/list-2 | P35: realestate.com.au | Q35: 46282
A36: SYD-035 | B36: 3 Bridge View Street, Blacktown | C36: Blacktown | D36: NSW | E36: 2148 | F36: 1200000 | G36: 46230 | H36: 5 | I36: 2 | J36: 2 | K36: 803 | L36: House | M36: =IF(AND(F36>=800000,F36<=1200000),"Yes","No") -> Yes | N36: https://www.realestate.com.au/sold/property-house-nsw-blacktown-151828512 | O36: https://www.realestate.com.au/sold/property-house-in-blacktown%2C%2Bnsw%2B2148/list-2 | P36: realestate.com.au | Q36: 46282
A37: SYD-036 | B37: 1/15 Bairin Street, Campbelltown | C37: Campbelltown | D37: NSW | E37: 2560 | F37: 775000 | G37: 46281 | H37: 3 | I37: 1 | J37: 2 | L37: House | M37: =IF(AND(F37>=800000,F37<=1200000),"Yes","No") -> No | N37: https://www.realestate.com.au/sold/property-house-nsw-campbelltown-152135028 | O37: https://www.realestate.com.au/sold/property-house-in-campbelltown%2C%2Bnsw%2B2560/list-1 | P37: realestate.com.au | Q37: 46282
A38: SYD-037 | B38: 5/167 Waminda Avenue, Campbelltown | C38: Campbelltown | D38: NSW | E38: 2560 | F38: 510000 | G38: 46279 | H38: 2 | I38: 1 | J38: 1 | L38: House | M38: =IF(AND(F38>=800000,F38<=1200000),"Yes","No") -> No | N38: https://www.realestate.com.au/sold/property-house-nsw-campbelltown-152165036 | O38: https://www.realestate.com.au/sold/property-house-in-campbelltown%2C%2Bnsw%2B2560/list-1 | P38: realestate.com.au | Q38: 46282
A39: SYD-038 | B39: 133 Dumaresq Street, Campbelltown | C39: Campbelltown | D39: NSW | E39: 2560 | F39: 951000 | G39: 46263 | H39: 3 | I39: 1 | K39: 701.9 | L39: House | M39: =IF(AND(F39>=800000,F39<=1200000),"Yes","No") -> Yes | N39: https://www.realestate.com.au/sold/property-house-nsw-campbelltown-152025204 | O39: https://www.realestate.com.au/sold/property-house-in-campbelltown%2C%2Bnsw%2B2560/list-1 | P39: realestate.com.au | Q39: 46282
A40: SYD-039 | B40: 5B Eddington Road, Campbelltown | C40: Campbelltown | D40: NSW | E40: 2560 | F40: 1030000 | G40: 46262 | H40: 4 | I40: 2 | J40: 1 | L40: House | M40: =IF(AND(F40>=800000,F40<=1200000),"Yes","No") -> Yes | N40: https://www.realestate.com.au/sold/property-duplex+semi-detached-nsw-campbelltown-152005580 | O40: https://www.realestate.com.au/sold/property-house-in-campbelltown%2C%2Bnsw%2B2560/list-1 | P40: realestate.com.au | Q40: 46282
...
